2022-05-02 23:03:07,828 INFO    MainThread:79888 [internal.py:wandb_internal():90] W&B internal server running at pid: 79888, started at: 2022-05-02 23:03:07.827245
2022-05-02 23:03:07,830 INFO    WriterThread:79888 [datastore.py:open_for_write():75] open: /Users/yskamto/Desktop/yu5uke/Poker/FP/FSP_Kuhn_Poker/wandb/run-20220502_230307-12o3mcxo/run-12o3mcxo.wandb
2022-05-02 23:03:07,832 DEBUG   SenderThread:79888 [sender.py:send():232] send: header
2022-05-02 23:03:07,832 DEBUG   SenderThread:79888 [sender.py:send():232] send: run
2022-05-02 23:03:37,289 DEBUG   HandlerThread:79888 [handler.py:handle_request():141] handle_request: shutdown
2022-05-02 23:03:37,290 INFO    HandlerThread:79888 [handler.py:finish():806] shutting down handler
2022-05-02 23:03:37,944 INFO    WriterThread:79888 [datastore.py:close():279] close: /Users/yskamto/Desktop/yu5uke/Poker/FP/FSP_Kuhn_Poker/wandb/run-20220502_230307-12o3mcxo/run-12o3mcxo.wandb
2022-05-02 23:03:41,649 ERROR   SenderThread:79888 [retry.py:__call__():126] Retry attempt failed:
Traceback (most recent call last):
  File "/Users/yskamto/miniforge3/envs/yskamto/lib/python3.8/site-packages/urllib3/connectionpool.py", line 445, in _make_request
    six.raise_from(e, None)
  File "<string>", line 3, in raise_from
  File "/Users/yskamto/miniforge3/envs/yskamto/lib/python3.8/site-packages/urllib3/connectionpool.py", line 440, in _make_request
    httplib_response = conn.getresponse()
  File "/Users/yskamto/miniforge3/envs/yskamto/lib/python3.8/http/client.py", line 1344, in getresponse
    response.begin()
  File "/Users/yskamto/miniforge3/envs/yskamto/lib/python3.8/http/client.py", line 307, in begin
    version, status, reason = self._read_status()
  File "/Users/yskamto/miniforge3/envs/yskamto/lib/python3.8/http/client.py", line 268, in _read_status
    line = str(self.fp.readline(_MAXLINE + 1), "iso-8859-1")
  File "/Users/yskamto/miniforge3/envs/yskamto/lib/python3.8/socket.py", line 669, in readinto
    return self._sock.recv_into(b)
  File "/Users/yskamto/miniforge3/envs/yskamto/lib/python3.8/ssl.py", line 1241, in recv_into
    return self.read(nbytes, buffer)
  File "/Users/yskamto/miniforge3/envs/yskamto/lib/python3.8/ssl.py", line 1099, in read
    return self._sslobj.read(len, buffer)
socket.timeout: The read operation timed out

During handling of the above exception, another exception occurred:

Traceback (most recent call last):
  File "/Users/yskamto/miniforge3/envs/yskamto/lib/python3.8/site-packages/requests/adapters.py", line 439, in send
    resp = conn.urlopen(
  File "/Users/yskamto/miniforge3/envs/yskamto/lib/python3.8/site-packages/urllib3/connectionpool.py", line 755, in urlopen
    retries = retries.increment(
  File "/Users/yskamto/miniforge3/envs/yskamto/lib/python3.8/site-packages/urllib3/util/retry.py", line 532, in increment
    raise six.reraise(type(error), error, _stacktrace)
  File "/Users/yskamto/miniforge3/envs/yskamto/lib/python3.8/site-packages/urllib3/packages/six.py", line 770, in reraise
    raise value
  File "/Users/yskamto/miniforge3/envs/yskamto/lib/python3.8/site-packages/urllib3/connectionpool.py", line 699, in urlopen
    httplib_response = self._make_request(
  File "/Users/yskamto/miniforge3/envs/yskamto/lib/python3.8/site-packages/urllib3/connectionpool.py", line 447, in _make_request
    self._raise_timeout(err=e, url=url, timeout_value=read_timeout)
  File "/Users/yskamto/miniforge3/envs/yskamto/lib/python3.8/site-packages/urllib3/connectionpool.py", line 336, in _raise_timeout
    raise ReadTimeoutError(
urllib3.exceptions.ReadTimeoutError: HTTPSConnectionPool(host='api.wandb.ai', port=443): Read timed out. (read timeout=10)

During handling of the above exception, another exception occurred:

Traceback (most recent call last):
  File "/Users/yskamto/miniforge3/envs/yskamto/lib/python3.8/site-packages/wandb/sdk/lib/retry.py", line 102, in __call__
    result = self._call_fn(*args, **kwargs)
  File "/Users/yskamto/miniforge3/envs/yskamto/lib/python3.8/site-packages/wandb/sdk/internal/internal_api.py", line 140, in execute
    return self.client.execute(*args, **kwargs)
  File "/Users/yskamto/miniforge3/envs/yskamto/lib/python3.8/site-packages/wandb/vendor/gql-0.2.0/wandb_gql/client.py", line 52, in execute
    result = self._get_result(document, *args, **kwargs)
  File "/Users/yskamto/miniforge3/envs/yskamto/lib/python3.8/site-packages/wandb/vendor/gql-0.2.0/wandb_gql/client.py", line 60, in _get_result
    return self.transport.execute(document, *args, **kwargs)
  File "/Users/yskamto/miniforge3/envs/yskamto/lib/python3.8/site-packages/wandb/vendor/gql-0.2.0/wandb_gql/transport/requests.py", line 38, in execute
    request = requests.post(self.url, **post_args)
  File "/Users/yskamto/miniforge3/envs/yskamto/lib/python3.8/site-packages/requests/api.py", line 119, in post
    return request('post', url, data=data, json=json, **kwargs)
  File "/Users/yskamto/miniforge3/envs/yskamto/lib/python3.8/site-packages/requests/api.py", line 61, in request
    return session.request(method=method, url=url, **kwargs)
  File "/Users/yskamto/miniforge3/envs/yskamto/lib/python3.8/site-packages/requests/sessions.py", line 542, in request
    resp = self.send(prep, **send_kwargs)
  File "/Users/yskamto/miniforge3/envs/yskamto/lib/python3.8/site-packages/requests/sessions.py", line 655, in send
    r = adapter.send(request, **kwargs)
  File "/Users/yskamto/miniforge3/envs/yskamto/lib/python3.8/site-packages/requests/adapters.py", line 529, in send
    raise ReadTimeout(e, request=request)
requests.exceptions.ReadTimeout: HTTPSConnectionPool(host='api.wandb.ai', port=443): Read timed out. (read timeout=10)
2022-05-02 23:03:50,287 INFO    SenderThread:79888 [dir_watcher.py:__init__():166] watching files in: /Users/yskamto/Desktop/yu5uke/Poker/FP/FSP_Kuhn_Poker/wandb/run-20220502_230307-12o3mcxo/files
2022-05-02 23:03:50,287 INFO    SenderThread:79888 [sender.py:_start_run_threads():811] run started: 12o3mcxo with start time 1651500187
2022-05-02 23:03:50,288 INFO    SenderThread:79888 [sender.py:finish():1106] shutting down sender
2022-05-02 23:03:50,288 INFO    SenderThread:79888 [dir_watcher.py:finish():279] shutting down directory watcher
2022-05-02 23:03:51,288 INFO    SenderThread:79888 [dir_watcher.py:finish():309] scan: /Users/yskamto/Desktop/yu5uke/Poker/FP/FSP_Kuhn_Poker/wandb/run-20220502_230307-12o3mcxo/files
2022-05-02 23:03:51,289 INFO    SenderThread:79888 [dir_watcher.py:finish():323] scan save: /Users/yskamto/Desktop/yu5uke/Poker/FP/FSP_Kuhn_Poker/wandb/run-20220502_230307-12o3mcxo/files/config.yaml config.yaml
2022-05-02 23:03:51,289 INFO    SenderThread:79888 [file_pusher.py:finish():145] shutting down file pusher
2022-05-02 23:03:51,289 INFO    SenderThread:79888 [file_pusher.py:join():150] waiting for file pusher
2022-05-02 23:03:56,190 INFO    Thread-9  :79888 [upload_job.py:push():137] Uploaded file /Users/yskamto/Desktop/yu5uke/Poker/FP/FSP_Kuhn_Poker/wandb/run-20220502_230307-12o3mcxo/files/config.yaml
2022-05-02 23:04:03,687 INFO    MainThread:79888 [internal.py:handle_exit():80] Internal process exited
